Workbook

Sheet README
B1: Commercial model: venture-diligence finalists F2 / F1 / F3
B3: Purpose
B4: Editable commercial model for the three finalists of the venture-opportunity search (post-red-team order: F2 > F1 > F3). It turns the research notes' pricing anchors, segment counts and cost drivers into unit economics, 10/100/1,000-customer scenarios, a 12-month path to first revenue for the lead finalist (F2), one-way and two-way sensitivities, and an operational-constraints check. Nothing in this workbook is a measured price: every price point is a Hypothesis inspired by a cited anchor and must be validated in customer interviews (experiments F2-A / F2-B / F1-A in decision_brief.md section 7).
B6: Finalists
B7: F2 = C&I open-access settlement / bill-audit + procurement engine for 1–20 MW industrial consumers in Karnataka, Tamil Nadu and Maharashtra (lead; success fee on recovered overcharges, then SaaS per site per year).
B8: F1 = ISTS connectivity / GNA intelligence for RE and BESS developers (per-developer subscription plus per-application reports). Gated by CTUIL data-reuse permission.
B9: F3 = FDRE / BESS dispatch, availability-compliance and IEX bid optimisation for Tier-2 storage awardees (₹ per MW per month, optional revenue share on merchant uplift). 2027+ watch item.
B11: How to use
B12: 1. Go to the Assumptions sheet. Cell C3 is the scenario selector: 1 = Conservative, 2 = Base, 3 = Upside. It drives the 'Active' column (F) on Assumptions, the 'Active' column on Unit economics, the Path to first revenue sheet and the Operational constraints sheet via INDEX.
B13: 2. Scenarios and Sensitivity do not depend on the selector: Scenarios shows all three scenarios side by side at 10 / 100 / 1,000 customers; Sensitivity is always computed on the Base column (D) of Assumptions.
B14: 3. Edit only blue cells. Every number in a blue cell is an input; every black cell is a formula; green cells are links to another sheet. Yellow-filled cells are the key levers and the unknowns that must be validated (CTUIL permission, IEX licence fee, recoverable % of bill).
B15: 4. Currency is INR throughout. The USD/INR rate (Assumptions C4) converts the USD-denominated compute and API costs; it is the only USD input.
... B27: Evidence base: research_notes/Venture scale opportunity search/ (decision_brief.md, opportunities_beyond_thesis.md, energy_software_india_forecasting.md, red_team_counterevidence.md, f1_customers_and_buying.md, solar_forecasting_feasibility.md, f2_f3_commercial_facts.md). No new web research was done for this workbook.

Sheet Assumptions
A1: Assumptions (edit blue cells only; column F = active scenario)
A3: Scenario selector (1 = Conservative, 2 = Base, 3 = Upside) | C3: 2 | D3: =CHOOSE($C$3,"Conservative","Base","Upside") -> Base
A4: USD / INR exchange rate (converts USD compute and API costs) | C4: 87 | G4: Estimate | H4: S37 | J4: Implied by JMK's listing of its OA report at INR 2 lakh + 18% GST ≈ USD 2,700 (₹2.36 lakh / 2,700 ≈ 87). Override with the live rate.
A6: Parameter | B6: Unit | C6: Conservative | D6: Base | E6: Upside | F6: Active | G6: Evidence class | H6: Source | I6: Must validate? | J6: Note / anchor
A7: Global cost drivers (shared by all finalists)
A8: Productive hours per FTE per month | B8: hours | C8: 160 | D8: 160 | E8: 160 | F8: =INDEX(C8:E8,1,$C$3) -> 160 | G8: Estimate | H8: S38 | I8: no | J8: Standard planning figure; used to convert support / onboarding hours into FTEs.
A9: Blended labour rate for onboarding and support (analyst) | B9: ₹ / hour | C9: 500 | D9: 400 | E9: 350 | F9: =INDEX(C9:E9,1,$C$3) -> 400 | G9: Hypothesis | H9: S38 | I9: YES | J9: ≈ ₹55–80k per month analyst salary ÷ 160 h. No salary data in the notes; user input.
A10: Engineer, fully loaded | B10: ₹ / month | C10: 200000 | D10: 150000 | E10: 125000 | F10: =INDEX(C10:E10,1,$C$3) -> 150000 | G10: Hypothesis | H10: S38 | I10: YES | J10: Bengaluru mid-level engineer; no salary data in the notes; user input.
A11: G&A fixed (accounting, legal, tools, insurance) | B11: ₹ / year | C11: 400000 | D11: 300000 | E11: 250000 | F11: =INDEX(C11:E11,1,$C$3) -> 300000 | G11: Hypothesis | H11: S38 | I11: no | J11: Solo-founder company overhead; user input.
A12: Fixed compute + object storage (bare VM, no paid APIs) | B12: US$ / month | C12: 40 | D12: 25 | E12: 15 | F12: =INDEX(C12:E12,1,$C$3) -> 25 | G12: Estimate | H12: S32 | I12: no | J12: solar_forecasting_feasibility.md section F: ≈ $15–40/month without paid APIs (2–4 vCPU VM + object storage).
A13: Open-Meteo Professional subscription (only where flagged) | B13: US$ / month | C13: 99 | D13: 99 | E13: 99 | F13: =INDEX(C13:E13,1,$C$3) -> 99 | G13: Verified | H13: S33 | I13: no | J13: Open-Meteo Professional $99/month (5M calls, historical / ensemble / satellite radiation). Needed only for F3's forecasting component.
A14: F2 — C&I open-access settlement & procurement engine (lead finalist)
A15: Reachable initial segment: OA / group-captive consumer organisations, 1–20 MW, Karnataka + TN + Maharashtra | B15: organisations | C15: 900 | D15: 1500 | E15: 3000 | F15: =INDEX(C15:E15,1,$C$3) -> 1500 | G15: Estimate | H15: S6 | I15: YES | J15: Karnataka: ≈922 distinct consumer organisations parsed from SLDC approved-consumer lists (count verified, de-duplication estimated; GESCOM/HESCOM lists missing). TN: '1,500+ MSME textile mills' on OA/group-captive (association claim, mostly <1 MW). Maharashtra: no public count. Range = Karnataka only → three states.
A16: OA energy drawn per site | B16: MU / year | C16: 10 | D16: 20 | E16: 35 | F16: =INDEX(C16:E16,1,$C$3) -> 20 | G16: Estimate | H16: S8 | I16: YES | J16: E.g. 5 MW contracted × 8,760 h × ~45% utilisation ≈ 20 MU. Cross-check: BESCOM-area OA drawal ≈ 6,230 MU/yr implied by the ₹1,028 Cr ÷ ₹1.65/kWh petition arithmetic.
A17: OA landed cost (energy + wheeling + CSS + surcharges + banking) | B17: ₹ / kWh | C17: 5 | D17: 5 | E17: 5 | F17: =INDEX(C17:E17,1,$C$3) -> 5 | G17: Estimate | H17: S11 | I17: no | J17: Hero Future Energies worked example: landed ₹4.78/unit vs DISCOM ₹7.32 (Manesar). Karnataka additional surcharge alone swung ₹0.82 → ₹0.40/kWh in FY26–27.
A18: Annual OA-related bill per site (formula) | B18: ₹ / site / year | C18: =C16*1000000*C17 -> 50000000 | D18: =D16*1000000*D17 -> 100000000 | E18: =E16*1000000*E17 -> 175000000 | F18: =INDEX(C18:E18,1,$C$3) -> 100000000 | G18: Estimate | H18: S8 | I18: no | J18: Formula: MU × 1,000,000 × ₹/kWh.
A19: Recoverable overcharge / avoidable loss as % of annual OA bill | B19: % of bill | C19: 0.005 | D19: 0.015 | E19: 0.03 | F19: =INDEX(C19:E19,1,$C$3) -> 0.015 | G19: Hypothesis | H19: S13 | I19: YES | J19: Experiment F2-A pass threshold: median ≥1.5% and ≥₹5 lakh/yr for 3 of 5 sites; fail <0.5%. Precedents: MERC-ordered wheeling refunds; ₹0.10/kWh error on 6,230 MU = ₹62 Cr/yr BESCOM-wide (arithmetic). MUST be measured on real bills.
A20: Success fee on verified recoveries | B20: % of recovered | C20: 0.2 | D20: 0.2 | E20: 0.25 | F20: =INDEX(C20:E20,1,$C$3) -> 0.2 | G20: Hypothesis | H20: S3 | I20: YES | J20: Audit-firm contingency structure (20–25%) and Zenatix's '% of energy bill' precedent (8–12% of bill). Not a quoted Indian OA fee: none published.
A21: Months of historical bills audited in the first engagement | B21: months | C21: 12 | D21: 18 | E21: 24 | F21: =INDEX(C21:E21,1,$C$3) -> 18 | G21: Hypothesis | H21: S13 | I21: no | J21: Experiment F2-A uses 12 months; refund windows after APTEL/MERC rulings can reach back 24 months.
A22: Recurring recoveries after the first audit (share of first-year recoverable) | B22: % of year-1 | C22: 0 | D22: 0.25 | E22: 0.5 | F22: =INDEX(C22:E22,1,$C$3) -> 0.25 | G22: Hypothesis | H22: S10 | I22: YES | J22: Charges are re-set every tariff order and banking regimes are re-litigated (TN banking rate changed 4×), so some errors recur. Conservative assumes none.
A23: SaaS subscription for monthly settlement + procurement optimisation | B23: ₹ / site / year | C23: 150000 | D23: 300000 | E23: 500000 | F23: =INDEX(C23:E23,1,$C$3) -> 300000 | G23: Hypothesis | H23: S3 | I23: YES | J23: Anchors: JMK OA report ₹2 lakh/yr (what buyers pay for OA data); mid-size factory energy audit ₹1.5–4 lakh; large plant ₹3–8 lakh. No OA-advisory fee is published by any Indian consultant.
A24: Billed sites per customer organisation | B24: sites | C24: 1 | D24: 1.5 | E24: 2 | F24: =INDEX(C24:E24,1,$C$3) -> 1.5 | G24: Estimate | H24: S6 | I24: no | J24: SLDC lists show multi-installation consumers (Shahi Exports ≥6 HT installations; Wipro, Infosys, RMZ, Manyata multiple RR numbers); most organisations have one.
A25: Win rate: qualified prospect → paying customer | B25: % | C25: 0.05 | D25: 0.1 | E25: 0.2 | F25: =INDEX(C25:E25,1,$C$3) -> 0.1 | G25: Hypothesis | H25: S13 | I25: YES | J25: Experiment F2-B pass = ≥3 of 10 interviewees accept a success-fee audit (30% pilot acceptance); paid conversion assumed lower. Incumbents (TPTCL, CES, OAE, BridgeIT) bundle settlement free, which caps the win rate.
A26: Sales cycle (first contact → signed) | B26: months | C26: 6 | D26: 4 | E26: 3 | F26: =INDEX(C26:E26,1,$C$3) -> 4 | G26: Hypothesis | H26: S14 | I26: YES | J26: Plant-head / CFO decision on a success-fee audit; no cycle data in the notes.
A27: Annual logo churn | B27: % / year | C27: 0.25 | D27: 0.15 | E27: 0.1 | F27: =INDEX(C27:E27,1,$C$3) -> 0.15 | G27: Hypothesis | H27: S14 | I27: YES | J27: Risk: developers / traders bundle settlement free; buyers may revert to the generator. No retention data exists.
A28: Onboarding hours per customer (collect 12–24 months of bills + SLDC / banking statements, identify regime) | B28: hours | C28: 40 | D28: 24 | E28: 16 | F28: =INDEX(C28:E28,1,$C$3) -> 24 | G28: Hypothesis | H28: S6 | I28: YES | J28: Two coexisting Karnataka banking regimes (legacy annual 2% in-kind vs 2025 monthly 8%) mean 'which regime applies' is manual work per generator pairing.
A29: Support + monthly statement handling per customer | B29: hours / month | C29: 4 | D29: 2.5 | E29: 1.5 | F29: =INDEX(C29:E29,1,$C$3) -> 2.5 | G29: Hypothesis | H29: S6 | I29: YES | J29: Monthly DISCOM bill + generator invoice + SLDC energy-accounting + banking statements per site; manual collection until DISCOM / SLDC exports are automated.
A30: Fixed data cost: JMK 'Open Access C&I RE Market' report subscription (incl. 18% GST) | B30: ₹ / year | C30: 236000 | D30: 236000 | E30: 236000 | F30: =INDEX(C30:E30,1,$C$3) -> 236000 | G30: Verified | H30: S2 | I30: no | J30: ₹2 lakh + GST, quarterly updates. Tariff orders / regulations are free public PDFs.
... A42: Months from audit finding to cash recovery (DISCOM credit or commission order) | B42: months | C42: 9 | D42: 6 | E42: 3 | F42: =INDEX(C42:E42,1,$C$3) -> 6 | G42: Hypothesis | H42: S10 | I42: YES | J42: Over-billing is corrected by commission orders (APTEL 366/2017, MERC 2025 refund orders): slow. Success-fee cash lags the finding.
A43: F1 — ISTS connectivity / GNA intelligence for RE & BESS developers
A44: Reachable initial segment: RE / BESS developers, lenders and advisors with live ISTS applications | B44: organisations | C44: 70 | D44: 200 | E44: 400 | F44: =INDEX(C44:E44,1,$C$3) -> 200 | G44: Estimate | H44: S16 | I44: YES | J44: ≈70 LoA-holding developers on CTUIL's 11/SM/2026 stranded list (verified count); 'a few hundred developers' nationally (brief); ≥25 named organisations with documented exposure.
A45: Subscription per developer | B45: ₹ / developer / year | C45: 300000 | D45: 500000 | E45: 1000000 | F45: =INDEX(C45:E45,1,$C$3) -> 500000 | G45: Hypothesis | H45: S15 | I45: YES | J45: H7 proposed ₹3–10 lakh/yr per developer seat, modelled on US interconnection-intelligence vendors; no Indian fee evidence. Sits below board-approval thresholds (inference).
A46: Paid per-application / per-substation reports per customer per year | B46: reports | C46: 0 | D46: 1 | E46: 2 | F46: =INDEX(C46:E46,1,$C$3) -> 1 | G46: Hypothesis | H46: S15 | I46: YES | J46: H7: ₹50k–2 lakh per report. Episodic need (60-day election windows, reallocation notices).
A47: Price per report | B47: ₹ / report | C47: 50000 | D47: 100000 | E47: 200000 | F47: =INDEX(C47:E47,1,$C$3) -> 100000 | G47: Hypothesis | H47: S15 | I47: YES | J47: Anchors: RERC consultancy estimate ₹10 lakh for a regulation-drafting assignment; law-firm CERC petition ₹10–50 lakh (unsourced estimate).
A48: Win rate: qualified prospect → paying customer | B48: % | C48: 0.05 | D48: 0.1 | E48: 0.15 | F48: =INDEX(C48:E48,1,$C$3) -> 0.1 | G48: Hypothesis | H48: S18 | I48: YES | J48: Tier-2 developers file their own CERC comments (in-house regulatory capacity); no software line item exists today.
A49: Sales cycle | B49: months | C49: 6 | D49: 4 | E49: 3 | F49: =INDEX(C49:E49,1,$C$3) -> 4 | G49: Hypothesis | H49: S18 | I49: YES | J49: BD / regulatory head discretionary budget (inference).
A50: Annual logo churn | B50: % / year | C50: 0.3 | D50: 0.2 | E50: 0.15 | F50: =INDEX(C50:E50,1,$C$3) -> 0.2 | G50: Hypothesis | H50: S21 | I50: YES | J50: Episodic need; CTUIL already publishes a filterable 636-row effective-connectivity table, so retention depends on the prediction / alert layer.
A51: Onboarding hours per customer (map portfolio of applications, alert rules) | B51: hours | C51: 16 | D51: 8 | E51: 6 | F51: =INDEX(C51:E51,1,$C$3) -> 8 | G51: Hypothesis | H51: S21 | I51: no | J51: Public data; customer supplies application IDs only.
A52: Support + alert curation per customer | B52: hours / month | C52: 3 | D52: 2 | E52: 1 | F52: =INDEX(C52:E52,1,$C$3) -> 2 | G52: Hypothesis | H52: S21 | I52: no | J52: Interpretation of CERC orders / CTUIL notices for the customer's substations.
A53: CTUIL written permission to reuse published data commercially (1 = obtained, 0 = refused / not yet) | B53: flag | C53: 0 | D53: 1 | E53: 1 | F53: =INDEX(C53:E53,1,$C$3) -> 1 | G53: Unknown | H53: S20 | I53: YES | J53: CTUIL copyright policy: contents 'may not be reproduced partially or fully, without due permission'; margin PDFs stamped RESTRICTED. Conservative = refused → revenue not bankable (F1-A0 gate).
...

Sheet Unit economics
A1: Unit economics per finalist (columns C–E = scenarios; F = active scenario)
A2: All cells are formulas on the Assumptions sheet. Steady-state ARPA excludes one-time fees. Payback uses steady-state gross margin. LTV = one-time fee + annual gross margin × (1 / churn), undiscounted.
F3: ="Active: "&Assumptions!$D$3 -> Active: Base
A4: Metric | B4: Unit | C4: Conservative | D4: Base | E4: Upside | F4: Active | G4: Formula / note
A5: F2 — C&I open-access settlement & procurement engine
A6: Annual OA bill per site | B6: ₹ / site / yr | C6: =Assumptions!C18 -> 50000000 | D6: =Assumptions!D18 -> 100000000 | E6: =Assumptions!E18 -> 175000000 | F6: =INDEX(C6:E6,1,Assumptions!$C$3) -> 100000000 | G6: Link: MU × ₹/kWh.
A7: SaaS revenue per account (sites × ₹/site/yr) | B7: ₹ / yr | C7: =Assumptions!C23*Assumptions!C24 -> 150000 | D7: =Assumptions!D23*Assumptions!D24 -> 450000 | E7: =Assumptions!E23*Assumptions!E24 -> 1000000 | F7: =INDEX(C7:E7,1,Assumptions!$C$3) -> 450000
A8: One-time audit success fee (first engagement) | B8: ₹ (one-time) | C8: =Assumptions!C18*Assumptions!C24*Assumptions!C19*Assumptions!C20*Assumptions!C21/12 -> 50000 | D8: =Assumptions!D18*Assumptions!D24*Assumptions!D19*Assumptions!D20*Assumptions!D21/12 -> 675000 | E8: =Assumptions!E18*Assumptions!E24*Assumptions!E19*Assumptions!E20*Assumptions!E21/12 -> 5250000 | F8: =INDEX(C8:E8,1,Assumptions!$C$3) -> 675000 | G8: Formula: bill × sites × recoverable % × fee % × months audited / 12.
A9: Recurring success fees per account per year | B9: ₹ / yr | C9: =Assumptions!C18*Assumptions!C24*Assumptions!C19*Assumptions!C20*Assumptions!C22 -> 0 | D9: =Assumptions!D18*Assumptions!D24*Assumptions!D19*Assumptions!D20*Assumptions!D22 -> 112500 | E9: =Assumptions!E18*Assumptions!E24*Assumptions!E19*Assumptions!E20*Assumptions!E22 -> 1312500 | F9: =INDEX(C9:E9,1,Assumptions!$C$3) -> 112500 | G9: Formula: bill × sites × recoverable % × fee % × recurring share.
A10: Year-1 revenue per account (SaaS + one-time fee) | B10: ₹ / yr | C10: =C7+C8 -> 200000 | D10: =D7+D8 -> 1125000 | E10: =E7+E8 -> 6250000 | F10: =INDEX(C10:E10,1,Assumptions!$C$3) -> 1125000
A11: ARPA, steady state (SaaS + recurring fees) | B11: ₹ / yr | C11: =C7+C9 -> 150000 | D11: =D7+D9 -> 562500 | E11: =E7+E9 -> 2312500 | F11: =INDEX(C11:E11,1,Assumptions!$C$3) -> 562500 | G11: Headline ARPA.
A12: Variable cost per account per year (data + compute + support hours × rate) | B12: ₹ / yr | C12: =Assumptions!C31+Assumptions!C32*12+Assumptions!C29*12*Assumptions!C9 -> 26400 | D12: =Assumptions!D31+Assumptions!D32*12+Assumptions!D29*12*Assumptions!D9 -> 13200 | E12: =Assumptions!E31+Assumptions!E32*12+Assumptions!E29*12*Assumptions!E9 -> 6900 | F12: =INDEX(C12:E12,1,Assumptions!$C$3) -> 13200
A13: Gross margin per account per year | B13: ₹ / yr | C13: =C11-C12 -> 123600 | D13: =D11-D12 -> 549300 | E13: =E11-E12 -> 2305600 | F13: =INDEX(C13:E13,1,Assumptions!$C$3) -> 549300
A14: Gross margin % | B14: % | C14: =IF(C11=0,0,C13/C11) -> 0.824 | D14: =IF(D11=0,0,D13/D11) -> 0.97653333 | E14: =IF(E11=0,0,E13/E11) -> 0.99701622 | F14: =INDEX(C14:E14,1,Assumptions!$C$3) -> 0.97653333
A15: CAC (outbound hours × rate + travel) ÷ win rate + event spend per new customer | B15: ₹ / customer | C15: =(Assumptions!C37*Assumptions!C9+Assumptions!C38)/Assumptions!C25+Assumptions!C39/Assumptions!C40 -> 170000 | D15: =(Assumptions!D37*Assumptions!D9+Assumptions!D38)/Assumptions!D25+Assumptions!D39/Assumptions!D40 -> 54000 | E15: =(Assumptions!E37*Assumptions!E9+Assumptions!E38)/Assumptions!E25+Assumptions!E39/Assumptions!E40 -> 17000 | F15: =INDEX(C15:E15,1,Assumptions!$C$3) -> 54000
A16: Onboarding cost (hours × rate) | B16: ₹ / customer | C16: =Assumptions!C28*Assumptions!C9 -> 20000 | D16: =Assumptions!D28*Assumptions!D9 -> 9600 | E16: =Assumptions!E28*Assumptions!E9 -> 5600 | F16: =INDEX(C16:E16,1,Assumptions!$C$3) -> 9600
A17: Total cost to acquire and onboard | B17: ₹ / customer | C17: =C15+C16 -> 190000 | D17: =D15+D16 -> 63600 | E17: =E15+E16 -> 22600 | F17: =INDEX(C17:E17,1,Assumptions!$C$3) -> 63600
A18: Payback on steady-state gross margin | B18: months | C18: =IF(C13<=0,"n/a (GM<=0)",C17/(C13/12)) -> 18.446602 | D18: =IF(D13<=0,"n/a (GM<=0)",D17/(D13/12)) -> 1.3894047 | E18: =IF(E13<=0,"n/a (GM<=0)",E17/(E13/12)) -> 0.11762665 | F18: =INDEX(C18:E18,1,Assumptions!$C$3) -> 1.3894047 | G18: Formula: (CAC + onboarding) ÷ (annual GM / 12).
A19: Payback net of one-time fee | B19: months | C19: =IF(C13<=0,"n/a (GM<=0)",MAX(0,C17-C8)/(C13/12)) -> 13.592233 | D19: =IF(D13<=0,"n/a (GM<=0)",MAX(0,D17-D8)/(D13/12)) -> 0 | E19: =IF(E13<=0,"n/a (GM<=0)",MAX(0,E17-E8)/(E13/12)) -> 0 | F19: =INDEX(C19:E19,1,Assumptions!$C$3) -> 0 | G19: One-time audit fee offsets acquisition cost (F2 only).
A20: Expected customer lifetime (1 / churn) | B20: years | C20: =IF(Assumptions!C27=0,0,1/Assumptions!C27) -> 4 | D20: =IF(Assumptions!D27=0,0,1/Assumptions!D27) -> 6.6666667 | E20: =IF(Assumptions!E27=0,0,1/Assumptions!E27) -> 10 | F20: =INDEX(C20:E20,1,Assumptions!$C$3) -> 6.6666667
A21: LTV (one-time fee + GM × lifetime, undiscounted) | B21: ₹ / customer | C21: =C8+C13*C20 -> 544400 | D21: =D8+D13*D20 -> 4337000 | E21: =E8+E13*E20 -> 28306000 | F21: =INDEX(C21:E21,1,Assumptions!$C$3) -> 4337000
A22: LTV / cost to acquire | B22: x | C22: =IF(C17=0,0,C21/C17) -> 2.8652632 | D22: =IF(D17=0,0,D21/D17) -> 68.191824 | E22: =IF(E17=0,0,E21/E17) -> 1252.4779 | F22: =INDEX(C22:E22,1,Assumptions!$C$3) -> 68.191824
A23: Receivables tied up per account (ARPA × DSO / 365) | B23: ₹ / customer | C23: =C11*Assumptions!C41/365 -> 24657.534 | D23: =D11*Assumptions!D41/365 -> 69349.315 | E23: =E11*Assumptions!E41/365 -> 190068.49 | F23: =INDEX(C23:E23,1,Assumptions!$C$3) -> 69349.315
A25: F1 — ISTS connectivity / GNA intelligence
A26: Subscription revenue per account | B26: ₹ / yr | C26: =Assumptions!C45 -> 300000 | D26: =Assumptions!D45 -> 500000 | E26: =Assumptions!E45 -> 1000000 | F26: =INDEX(C26:E26,1,Assumptions!$C$3) -> 500000
A27: Report revenue per account per year | B27: ₹ / yr | C27: =Assumptions!C46*Assumptions!C47 -> 0 | D27: =Assumptions!D46*Assumptions!D47 -> 100000 | E27: =Assumptions!E46*Assumptions!E47 -> 400000 | F27: =INDEX(C27:E27,1,Assumptions!$C$3) -> 100000
A28: One-time fees | B28: ₹ (one-time) | C28: =0 -> 0 | D28: =0 -> 0 | E28: =0 -> 0 | F28: =INDEX(C28:E28,1,Assumptions!$C$3) -> 0 | G28: None modelled.
A29: ARPA, steady state | B29: ₹ / yr | C29: =C26+C27 -> 300000 | D29: =D26+D27 -> 600000 | E29: =E26+E27 -> 1400000 | F29: =INDEX(C29:E29,1,Assumptions!$C$3) -> 600000 | G29: Headline ARPA (before the CTUIL gate).
A30: CTUIL permission gate (1 = permission assumed, 0 = blocked) | B30: flag | C30: =Assumptions!C53 -> 0 | D30: =Assumptions!D53 -> 1 | E30: =Assumptions!E53 -> 1 | F30: =INDEX(C30:E30,1,Assumptions!$C$3) -> 1 | G30: Conservative = refused. If 0, revenue is not bankable: see Scenarios.
A31: Bankable ARPA (ARPA × gate) | B31: ₹ / yr | C31: =C29*C30 -> 0 | D31: =D29*D30 -> 600000 | E31: =E29*E30 -> 1400000 | F31: =INDEX(C31:E31,1,Assumptions!$C$3) -> 600000
A32: Variable cost per account per year (data + compute + support hours × rate) | B32: ₹ / yr | C32: =Assumptions!C55+Assumptions!C56*12+Assumptions!C52*12*Assumptions!C9 -> 19200 | D32: =Assumptions!D55+Assumptions!D56*12+Assumptions!D52*12*Assumptions!D9 -> 10200 | E32: =Assumptions!E55+Assumptions!E56*12+Assumptions!E52*12*Assumptions!E9 -> 4500 | F32: =INDEX(C32:E32,1,Assumptions!$C$3) -> 10200
A33: Gross margin per account per year | B33: ₹ / yr | C33: =C29-C32 -> 280800 | D33: =D29-D32 -> 589800 | E33: =E29-E32 -> 1395500 | F33: =INDEX(C33:E33,1,Assumptions!$C$3) -> 589800
A34: Gross margin % | B34: % | C34: =IF(C29=0,0,C33/C29) -> 0.936 | D34: =IF(D29=0,0,D33/D29) -> 0.983 | E34: =IF(E29=0,0,E33/E29) -> 0.99678571 | F34: =INDEX(C34:E34,1,Assumptions!$C$3) -> 0.983
A35: CAC (outbound hours × rate + travel) ÷ win rate + event spend per new customer | B35: ₹ / customer | C35: =(Assumptions!C61*Assumptions!C9+Assumptions!C62)/Assumptions!C48+Assumptions!C63/Assumptions!C64 -> 450000 | D35: =(Assumptions!D61*Assumptions!D9+Assumptions!D62)/Assumptions!D48+Assumptions!D63/Assumptions!D64 -> 150750 | E35: =(Assumptions!E61*Assumptions!E9+Assumptions!E62)/Assumptions!E48+Assumptions!E63/Assumptions!E64 -> 60666.667 | F35: =INDEX(C35:E35,1,Assumptions!$C$3) -> 150750
A36: Onboarding cost (hours × rate) | B36: ₹ / customer | C36: =Assumptions!C51*Assumptions!C9 -> 8000 | D36: =Assumptions!D51*Assumptions!D9 -> 3200 | E36: =Assumptions!E51*Assumptions!E9 -> 2100 | F36: =INDEX(C36:E36,1,Assumptions!$C$3) -> 3200
A37: Total cost to acquire and onboard | B37: ₹ / customer | C37: =C35+C36 -> 458000 | D37: =D35+D36 -> 153950 | E37: =E35+E36 -> 62766.667 | F37: =INDEX(C37:E37,1,Assumptions!$C$3) -> 153950
A38: Payback on steady-state gross margin | B38: months | C38: =IF(C33<=0,"n/a (GM<=0)",C37/(C33/12)) -> 19.57265 | D38: =IF(D33<=0,"n/a (GM<=0)",D37/(D33/12)) -> 3.1322482 | E38: =IF(E33<=0,"n/a (GM<=0)",E37/(E33/12)) -> 0.53973486 | F38: =INDEX(C38:E38,1,Assumptions!$C$3) -> 3.1322482 | G38: Formula: (CAC + onboarding) ÷ (annual GM / 12).
A39: Payback net of one-time fee | B39: months | C39: =IF(C33<=0,"n/a (GM<=0)",MAX(0,C37-C28)/(C33/12)) -> 19.57265 | D39: =IF(D33<=0,"n/a (GM<=0)",MAX(0,D37-D28)/(D33/12)) -> 3.1322482 | E39: =IF(E33<=0,"n/a (GM<=0)",MAX(0,E37-E28)/(E33/12)) -> 0.53973486 | F39: =INDEX(C39:E39,1,Assumptions!$C$3) -> 3.1322482 | G39: One-time audit fee offsets acquisition cost (F2 only).
A40: Expected customer lifetime (1 / churn) | B40: years | C40: =IF(Assumptions!C50=0,0,1/Assumptions!C50) -> 3.3333333 | D40: =IF(Assumptions!D50=0,0,1/Assumptions!D50) -> 5 | E40: =IF(Assumptions!E50=0,0,1/Assumptions!E50) -> 6.6666667 | F40: =INDEX(C40:E40,1,Assumptions!$C$3) -> 5
A41: LTV (one-time fee + GM × lifetime, undiscounted) | B41: ₹ / customer | C41: =C28+C33*C40 -> 936000 | D41: =D28+D33*D40 -> 2949000 | E41: =E28+E33*E40 -> 9303333.3 | F41: =INDEX(C41:E41,1,Assumptions!$C$3) -> 2949000
...

Sheet Path to first revenue
A1: Path to first revenue — F2, month-by-month (active scenario)
A2: ="Active scenario: "&Assumptions!$D$3&". Blue cells are inputs; the pilot plan (row 19) is the main lever." -> Active scenario: Base. Blue cells are inputs; the pilot plan (row 19) is the main lever.
A4: Input | B4: Value | O4: Note
A5: Founder capital available | B5: 1000000 | O5: Default ₹10 lakh (brief: founder has limited capital).
A6: Founder stipend | B6: 50000 | O6: ₹ per month, cash. Also used as founder cost in Scenarios opex.
A7: Founder delivery hours available per month (audits + support) | B7: 80 | O7: Remaining founder time goes to sales and building.
A8: Prospect meetings per pilot started | B8: 5 | O8: Travel cost driver: meetings × ₹ per prospect trip.
A9: Pilot → paying conversion rate | B9: 0.3 | O9: Experiment F2-B pass threshold: ≥3 of 10 accept a success-fee audit. Hypothesis.
A10: Months from pilot start to conversion | B10: =ROUND(Assumptions!$F$26,0) -> 4 | O10: Link: active sales cycle.
A11: Months from conversion to recovery cash (audit fee billable) | B11: =ROUND(Assumptions!$F$42,0) -> 6 | O11: Link: active recovery lag.
A12: DSO in months (rounded) | B12: =ROUND(Assumptions!$F$41/30,0) -> 2 | O12: Link: active DSO / 30.
A13: SaaS billing per paying customer per month | B13: ='Unit economics'!$F$7/12 -> 37500 | O13: Link: active ARPA (SaaS) / 12.
A14: One-time audit success fee per conversion | B14: ='Unit economics'!$F$8 -> 675000 | O14: Link: active one-time fee.
A15: Audit / onboarding hours per pilot | B15: =Assumptions!$F$28 -> 24 | O15: Link.
A16: Support hours per paying customer per month | B16: =Assumptions!$F$29 -> 2.5 | O16: Link.
A17: Contract analyst rate (₹/hour) when founder hours are exceeded | B17: =Assumptions!$F$9 -> 400 | O17: Link.
A18: Travel per prospect meeting | B18: =Assumptions!$F$38 -> 2000 | O18: Link.
A19: Fixed compute per month (₹) | B19: =Assumptions!$F$12*Assumptions!$C$4 -> 2175 | O19: Link: bare VM $ × USD/INR.
A20: Compute per paying customer per month | B20: =Assumptions!$F$32 -> 100 | O20: Link.
A21: Events spend per month | B21: =Assumptions!$F$39/12 -> 8333.3333 | O21: Link: annual / 12.
A22: Data subscription per month (JMK report) | B22: =Assumptions!$F$30/12 -> 19666.667 | O22: Link: annual / 12.
A24: Month | C24: M1 | D24: M2 | E24: M3 | F24: M4 | G24: M5 | H24: M6 | I24: M7 | J24: M8 | K24: M9 | L24: M10 | M24: M11 | N24: M12 | O24: Note
A25: Month number | C25: 1 | D25: 2 | E25: 3 | F25: 4 | G25: 5 | H25: 6 | I25: 7 | J25: 8 | K25: 9 | L25: 10 | M25: 11 | N25: 12
A26: Pilots (success-fee audits) started | C26: 1 | D26: 2 | E26: 2 | F26: 2 | G26: 2 | H26: 2 | I26: 2 | J26: 2 | K26: 2 | L26: 2 | M26: 2 | N26: 2 | O26: INPUT: pilot plan. Default: 1 in month 1 then 2 per month.
A27: Conversions to paying (pilots started 'cycle' months earlier × conversion rate) | C27: =IF(C25-$B$10>=1,INDEX($C$26:$N$26,1,C25-$B$10)*$B$9,0) -> 0 | D27: =IF(D25-$B$10>=1,INDEX($C$26:$N$26,1,D25-$B$10)*$B$9,0) -> 0 | E27: =IF(E25-$B$10>=1,INDEX($C$26:$N$26,1,E25-$B$10)*$B$9,0) -> 0 | F27: =IF(F25-$B$10>=1,INDEX($C$26:$N$26,1,F25-$B$10)*$B$9,0) -> 0 | G27: =IF(G25-$B$10>=1,INDEX($C$26:$N$26,1,G25-$B$10)*$B$9,0) -> 0.3 | H27: =IF(H25-$B$10>=1,INDEX($C$26:$N$26,1,H25-$B$10)*$B$9,0) -> 0.6 | I27: =IF(I25-$B$10>=1,INDEX($C$26:$N$26,1,I25-$B$10)*$B$9,0) -> 0.6 | J27: =IF(J25-$B$10>=1,INDEX($C$26:$N$26,1,J25-$B$10)*$B$9,0) -> 0.6 | ... N27: =IF(N25-$B$10>=1,INDEX($C$26:$N$26,1,N25-$B$10)*$B$9,0) -> 0.6
A28: Paying customers (cumulative) | C28: =C27 -> 0 | D28: =C28+D27 -> 0 | E28: =D28+E27 -> 0 | F28: =E28+F27 -> 0 | G28: =F28+G27 -> 0.3 | H28: =G28+H27 -> 0.9 | I28: =H28+I27 -> 1.5 | J28: =I28+J27 -> 2.1 | K28: =J28+K27 -> 2.7 | ... N28: =M28+N27 -> 4.5
A29: SaaS billed | C29: =C28*$B$13 -> 0 | D29: =D28*$B$13 -> 0 | E29: =E28*$B$13 -> 0 | F29: =F28*$B$13 -> 0 | G29: =G28*$B$13 -> 11250 | H29: =H28*$B$13 -> 33750 | I29: =I28*$B$13 -> 56250 | J29: =J28*$B$13 -> 78750 | ... N29: =N28*$B$13 -> 168750
A30: Audit success fee billed (conversions 'lag' months earlier × fee) | C30: =IF(C25-$B$11>=1,INDEX($C$27:$N$27,1,C25-$B$11)*$B$14,0) -> 0 | D30: =IF(D25-$B$11>=1,INDEX($C$27:$N$27,1,D25-$B$11)*$B$14,0) -> 0 | E30: =IF(E25-$B$11>=1,INDEX($C$27:$N$27,1,E25-$B$11)*$B$14,0) -> 0 | F30: =IF(F25-$B$11>=1,INDEX($C$27:$N$27,1,F25-$B$11)*$B$14,0) -> 0 | G30: =IF(G25-$B$11>=1,INDEX($C$27:$N$27,1,G25-$B$11)*$B$14,0) -> 0 | H30: =IF(H25-$B$11>=1,INDEX($C$27:$N$27,1,H25-$B$11)*$B$14,0) -> 0 | I30: =IF(I25-$B$11>=1,INDEX($C$27:$N$27,1,I25-$B$11)*$B$14,0) -> 0 | J30: =IF(J25-$B$11>=1,INDEX($C$27:$N$27,1,J25-$B$11)*$B$14,0) -> 0 | ... N30: =IF(N25-$B$11>=1,INDEX($C$27:$N$27,1,N25-$B$11)*$B$14,0) -> 405000
A31: Revenue recognised (billed) | C31: =C29+C30 -> 0 | D31: =D29+D30 -> 0 | E31: =E29+E30 -> 0 | F31: =F29+F30 -> 0 | G31: =G29+G30 -> 11250 | H31: =H29+H30 -> 33750 | I31: =I29+I30 -> 56250 | J31: =J29+J30 -> 78750 | ... N31: =N29+N30 -> 573750
A32: Cash in: SaaS (billed 'DSO months' earlier) | C32: =IF(C25-$B$12>=1,INDEX($C$29:$N$29,1,C25-$B$12),0) -> 0 | D32: =IF(D25-$B$12>=1,INDEX($C$29:$N$29,1,D25-$B$12),0) -> 0 | E32: =IF(E25-$B$12>=1,INDEX($C$29:$N$29,1,E25-$B$12),0) -> 0 | F32: =IF(F25-$B$12>=1,INDEX($C$29:$N$29,1,F25-$B$12),0) -> 0 | G32: =IF(G25-$B$12>=1,INDEX($C$29:$N$29,1,G25-$B$12),0) -> 0 | H32: =IF(H25-$B$12>=1,INDEX($C$29:$N$29,1,H25-$B$12),0) -> 0 | I32: =IF(I25-$B$12>=1,INDEX($C$29:$N$29,1,I25-$B$12),0) -> 11250 | J32: =IF(J25-$B$12>=1,INDEX($C$29:$N$29,1,J25-$B$12),0) -> 33750 | ... N32: =IF(N25-$B$12>=1,INDEX($C$29:$N$29,1,N25-$B$12),0) -> 123750
A33: Cash in: audit fees (billed 'DSO months' earlier) | C33: =IF(C25-$B$12>=1,INDEX($C$30:$N$30,1,C25-$B$12),0) -> 0 | D33: =IF(D25-$B$12>=1,INDEX($C$30:$N$30,1,D25-$B$12),0) -> 0 | E33: =IF(E25-$B$12>=1,INDEX($C$30:$N$30,1,E25-$B$12),0) -> 0 | F33: =IF(F25-$B$12>=1,INDEX($C$30:$N$30,1,F25-$B$12),0) -> 0 | G33: =IF(G25-$B$12>=1,INDEX($C$30:$N$30,1,G25-$B$12),0) -> 0 | H33: =IF(H25-$B$12>=1,INDEX($C$30:$N$30,1,H25-$B$12),0) -> 0 | I33: =IF(I25-$B$12>=1,INDEX($C$30:$N$30,1,I25-$B$12),0) -> 0 | J33: =IF(J25-$B$12>=1,INDEX($C$30:$N$30,1,J25-$B$12),0) -> 0 | ... N33: =IF(N25-$B$12>=1,INDEX($C$30:$N$30,1,N25-$B$12),0) -> 0
A34: Total cash in | C34: =C32+C33 -> 0 | D34: =D32+D33 -> 0 | E34: =E32+E33 -> 0 | F34: =F32+F33 -> 0 | G34: =G32+G33 -> 0 | H34: =H32+H33 -> 0 | I34: =I32+I33 -> 11250 | J34: =J32+J33 -> 33750 | ... N34: =N32+N33 -> 123750
A35: Delivery hours needed (pilots × audit hours + customers × support hours) | C35: =C26*$B$15+C28*$B$16 -> 24 | D35: =D26*$B$15+D28*$B$16 -> 48 | E35: =E26*$B$15+E28*$B$16 -> 48 | F35: =F26*$B$15+F28*$B$16 -> 48 | G35: =G26*$B$15+G28*$B$16 -> 48.75 | H35: =H26*$B$15+H28*$B$16 -> 50.25 | I35: =I26*$B$15+I28*$B$16 -> 51.75 | J35: =J26*$B$15+J28*$B$16 -> 53.25 | ... N35: =N26*$B$15+N28*$B$16 -> 59.25
A36: Cost: founder stipend | C36: =$B$6 -> 50000 | D36: =$B$6 -> 50000 | E36: =$B$6 -> 50000 | F36: =$B$6 -> 50000 | G36: =$B$6 -> 50000 | H36: =$B$6 -> 50000 | I36: =$B$6 -> 50000 | J36: =$B$6 -> 50000 | ... N36: =$B$6 -> 50000
A37: Cost: contract analyst (hours above founder capacity × rate) | C37: =MAX(0,C35-$B$7)*$B$17 -> 0 | D37: =MAX(0,D35-$B$7)*$B$17 -> 0 | E37: =MAX(0,E35-$B$7)*$B$17 -> 0 | F37: =MAX(0,F35-$B$7)*$B$17 -> 0 | G37: =MAX(0,G35-$B$7)*$B$17 -> 0 | H37: =MAX(0,H35-$B$7)*$B$17 -> 0 | I37: =MAX(0,I35-$B$7)*$B$17 -> 0 | J37: =MAX(0,J35-$B$7)*$B$17 -> 0 | ... N37: =MAX(0,N35-$B$7)*$B$17 -> 0
A38: Cost: compute (fixed + per customer) | C38: =$B$19+C28*$B$20 -> 2175 | D38: =$B$19+D28*$B$20 -> 2175 | E38: =$B$19+E28*$B$20 -> 2175 | F38: =$B$19+F28*$B$20 -> 2175 | G38: =$B$19+G28*$B$20 -> 2205 | H38: =$B$19+H28*$B$20 -> 2265 | I38: =$B$19+I28*$B$20 -> 2325 | J38: =$B$19+J28*$B$20 -> 2385 | ... N38: =$B$19+N28*$B$20 -> 2625
A39: Cost: travel (pilots × meetings × ₹/trip) | C39: =C26*$B$8*$B$18 -> 10000 | D39: =D26*$B$8*$B$18 -> 20000 | E39: =E26*$B$8*$B$18 -> 20000 | F39: =F26*$B$8*$B$18 -> 20000 | G39: =G26*$B$8*$B$18 -> 20000 | H39: =H26*$B$8*$B$18 -> 20000 | I39: =I26*$B$8*$B$18 -> 20000 | J39: =J26*$B$8*$B$18 -> 20000 | ... N39: =N26*$B$8*$B$18 -> 20000
A40: Cost: events / associations | C40: =$B$21 -> 8333.3333 | D40: =$B$21 -> 8333.3333 | E40: =$B$21 -> 8333.3333 | F40: =$B$21 -> 8333.3333 | G40: =$B$21 -> 8333.3333 | H40: =$B$21 -> 8333.3333 | I40: =$B$21 -> 8333.3333 | J40: =$B$21 -> 8333.3333 | ... N40: =$B$21 -> 8333.3333
A41: Cost: data subscription | C41: =$B$22 -> 19666.667 | D41: =$B$22 -> 19666.667 | E41: =$B$22 -> 19666.667 | F41: =$B$22 -> 19666.667 | G41: =$B$22 -> 19666.667 | H41: =$B$22 -> 19666.667 | I41: =$B$22 -> 19666.667 | J41: =$B$22 -> 19666.667 | ... N41: =$B$22 -> 19666.667
A42: Total cash out (burn) | C42: =SUM(C36:C41) -> 90175 | D42: =SUM(D36:D41) -> 100175 | E42: =SUM(E36:E41) -> 100175 | F42: =SUM(F36:F41) -> 100175 | G42: =SUM(G36:G41) -> 100205 | H42: =SUM(H36:H41) -> 100265 | I42: =SUM(I36:I41) -> 100325 | J42: =SUM(J36:J41) -> 100385 | ... N42: =SUM(N36:N41) -> 100625
...

Sheet Scenarios
A1: Scenarios — steady-state annual P&L at 10 / 100 / 1,000 customers, all three scenarios
A2: Independent of the selector. Customer counts in row 5 are inputs. Opex includes replacement acquisition (customers × churn × cost to acquire). Feasibility flags compare the customer count with the reachable segment and with segment × win rate.
C4: Conservative | F4: Base | I4: Upside | L4: Note
A5: Customers (input) | C5: 10 | D5: 100 | E5: 1000 | F5: 10 | G5: 100 | H5: 1000 | I5: 10 | J5: 100 | K5: 1000
A7: F2 — C&I open-access settlement & procurement engine
A8: Customers | B8: count | C8: =C$5 -> 10 | D8: =D$5 -> 100 | E8: =E$5 -> 1000 | F8: =F$5 -> 10 | G8: =G$5 -> 100 | H8: =H$5 -> 1000 | I8: =I$5 -> 10 | J8: =J$5 -> 100 | K8: =K$5 -> 1000
A9: Recurring revenue (customers × steady-state ARPA) | B9: ₹ / yr | C9: =C$5*'Unit economics'!$C$11 -> 1500000 | D9: =D$5*'Unit economics'!$C$11 -> 15000000 | E9: =E$5*'Unit economics'!$C$11 -> 150000000 | F9: =F$5*'Unit economics'!$D$11 -> 5625000 | G9: =G$5*'Unit economics'!$D$11 -> 56250000 | H9: =H$5*'Unit economics'!$D$11 -> 562500000 | I9: =I$5*'Unit economics'!$E$11 -> 23125000 | J9: =J$5*'Unit economics'!$E$11 -> 231250000 | K9: =K$5*'Unit economics'!$E$11 -> 2312500000
A10: One-time fees on replacement customers (customers × churn × one-time fee) | B10: ₹ / yr | C10: =C$5*Assumptions!$C$27*'Unit economics'!$C$8 -> 125000 | D10: =D$5*Assumptions!$C$27*'Unit economics'!$C$8 -> 1250000 | E10: =E$5*Assumptions!$C$27*'Unit economics'!$C$8 -> 12500000 | F10: =F$5*Assumptions!$D$27*'Unit economics'!$D$8 -> 1012500 | G10: =G$5*Assumptions!$D$27*'Unit economics'!$D$8 -> 10125000 | H10: =H$5*Assumptions!$D$27*'Unit economics'!$D$8 -> 101250000 | I10: =I$5*Assumptions!$E$27*'Unit economics'!$E$8 -> 5250000 | J10: =J$5*Assumptions!$E$27*'Unit economics'!$E$8 -> 52500000 | K10: =K$5*Assumptions!$E$27*'Unit economics'!$E$8 -> 525000000
A11: Total revenue | B11: ₹ / yr | C11: =C9+C10 -> 1625000 | D11: =D9+D10 -> 16250000 | E11: =E9+E10 -> 162500000 | F11: =F9+F10 -> 6637500 | G11: =G9+G10 -> 66375000 | H11: =H9+H10 -> 663750000 | I11: =I9+I10 -> 28375000 | J11: =J9+J10 -> 283750000 | K11: =K9+K10 -> 2837500000
A12: COGS (customers × variable cost) | B12: ₹ / yr | C12: =C$5*'Unit economics'!$C$12 -> 264000 | D12: =D$5*'Unit economics'!$C$12 -> 2640000 | E12: =E$5*'Unit economics'!$C$12 -> 26400000 | F12: =F$5*'Unit economics'!$D$12 -> 132000 | G12: =G$5*'Unit economics'!$D$12 -> 1320000 | H12: =H$5*'Unit economics'!$D$12 -> 13200000 | I12: =I$5*'Unit economics'!$E$12 -> 69000 | J12: =J$5*'Unit economics'!$E$12 -> 690000 | K12: =K$5*'Unit economics'!$E$12 -> 6900000
A13: Gross margin | B13: ₹ / yr | C13: =C11-C12 -> 1361000 | D13: =D11-D12 -> 13610000 | E13: =E11-E12 -> 136100000 | F13: =F11-F12 -> 6505500 | G13: =G11-G12 -> 65055000 | H13: =H11-H12 -> 650550000 | I13: =I11-I12 -> 28306000 | J13: =J11-J12 -> 283060000 | K13: =K11-K12 -> 2830600000
A14: Gross margin % | B14: % | C14: =IF(C11=0,0,C13/C11) -> 0.83753846 | D14: =IF(D11=0,0,D13/D11) -> 0.83753846 | E14: =IF(E11=0,0,E13/E11) -> 0.83753846 | F14: =IF(F11=0,0,F13/F11) -> 0.98011299 | G14: =IF(G11=0,0,G13/G11) -> 0.98011299 | H14: =IF(H11=0,0,H13/H11) -> 0.98011299 | I14: =IF(I11=0,0,I13/I11) -> 0.99756828 | J14: =IF(J11=0,0,J13/J11) -> 0.99756828 | K14: =IF(K11=0,0,K13/K11) -> 0.99756828
A15: Engineers at this stage (excl. founder) | B15: FTE | C15: =IF(C$5<=10,Assumptions!$C$34,IF(C$5<=100,Assumptions!$C$35,Assumptions!$C$36)) -> 0 | D15: =IF(D$5<=10,Assumptions!$C$34,IF(D$5<=100,Assumptions!$C$35,Assumptions!$C$36)) -> 2 | E15: =IF(E$5<=10,Assumptions!$C$34,IF(E$5<=100,Assumptions!$C$35,Assumptions!$C$36)) -> 4 | F15: =IF(F$5<=10,Assumptions!$D$34,IF(F$5<=100,Assumptions!$D$35,Assumptions!$D$36)) -> 0 | G15: =IF(G$5<=10,Assumptions!$D$34,IF(G$5<=100,Assumptions!$D$35,Assumptions!$D$36)) -> 1 | H15: =IF(H$5<=10,Assumptions!$D$34,IF(H$5<=100,Assumptions!$D$35,Assumptions!$D$36)) -> 2 | I15: =IF(I$5<=10,Assumptions!$E$34,IF(I$5<=100,Assumptions!$E$35,Assumptions!$E$36)) -> 0 | J15: =IF(J$5<=10,Assumptions!$E$34,IF(J$5<=100,Assumptions!$E$35,Assumptions!$E$36)) -> 1 | K15: =IF(K$5<=10,Assumptions!$E$34,IF(K$5<=100,Assumptions!$E$35,Assumptions!$E$36)) -> 2 | L15: Stage lookup on Assumptions eng10 / eng100 / eng1000.
A16: Opex: founder stipend | B16: ₹ / yr | C16: ='Path to first revenue'!$B$6*12 -> 600000 | D16: ='Path to first revenue'!$B$6*12 -> 600000 | E16: ='Path to first revenue'!$B$6*12 -> 600000 | F16: ='Path to first revenue'!$B$6*12 -> 600000 | G16: ='Path to first revenue'!$B$6*12 -> 600000 | H16: ='Path to first revenue'!$B$6*12 -> 600000 | I16: ='Path to first revenue'!$B$6*12 -> 600000 | J16: ='Path to first revenue'!$B$6*12 -> 600000 | K16: ='Path to first revenue'!$B$6*12 -> 600000 | L16: From Path to first revenue (input).
A17: Opex: engineers | B17: ₹ / yr | C17: =C15*Assumptions!$C$10*12 -> 0 | D17: =D15*Assumptions!$C$10*12 -> 4800000 | E17: =E15*Assumptions!$C$10*12 -> 9600000 | F17: =F15*Assumptions!$D$10*12 -> 0 | G17: =G15*Assumptions!$D$10*12 -> 1800000 | H17: =H15*Assumptions!$D$10*12 -> 3600000 | I17: =I15*Assumptions!$E$10*12 -> 0 | J17: =J15*Assumptions!$E$10*12 -> 1500000 | K17: =K15*Assumptions!$E$10*12 -> 3000000
A18: Opex: G&A fixed | B18: ₹ / yr | C18: =Assumptions!$C$11 -> 400000 | D18: =Assumptions!$C$11 -> 400000 | E18: =Assumptions!$C$11 -> 400000 | F18: =Assumptions!$D$11 -> 300000 | G18: =Assumptions!$D$11 -> 300000 | H18: =Assumptions!$D$11 -> 300000 | I18: =Assumptions!$E$11 -> 250000 | J18: =Assumptions!$E$11 -> 250000 | K18: =Assumptions!$E$11 -> 250000
A19: Opex: conferences / events | B19: ₹ / yr | C19: =Assumptions!$C$39 -> 150000 | D19: =Assumptions!$C$39 -> 150000 | E19: =Assumptions!$C$39 -> 150000 | F19: =Assumptions!$D$39 -> 100000 | G19: =Assumptions!$D$39 -> 100000 | H19: =Assumptions!$D$39 -> 100000 | I19: =Assumptions!$E$39 -> 50000 | J19: =Assumptions!$E$39 -> 50000 | K19: =Assumptions!$E$39 -> 50000
A20: Opex: fixed data / licence | B20: ₹ / yr | C20: =Assumptions!$C$30 -> 236000 | D20: =Assumptions!$C$30 -> 236000 | E20: =Assumptions!$C$30 -> 236000 | F20: =Assumptions!$D$30 -> 236000 | G20: =Assumptions!$D$30 -> 236000 | H20: =Assumptions!$D$30 -> 236000 | I20: =Assumptions!$E$30 -> 236000 | J20: =Assumptions!$E$30 -> 236000 | K20: =Assumptions!$E$30 -> 236000 | L20: JMK report.
A21: Opex: fixed compute (+ Open-Meteo if flagged) × USD/INR | B21: ₹ / yr | C21: =(Assumptions!$C$12+Assumptions!$C$33*Assumptions!$C$13)*Assumptions!$C$4*12 -> 41760 | D21: =(Assumptions!$C$12+Assumptions!$C$33*Assumptions!$C$13)*Assumptions!$C$4*12 -> 41760 | E21: =(Assumptions!$C$12+Assumptions!$C$33*Assumptions!$C$13)*Assumptions!$C$4*12 -> 41760 | F21: =(Assumptions!$D$12+Assumptions!$D$33*Assumptions!$D$13)*Assumptions!$C$4*12 -> 26100 | G21: =(Assumptions!$D$12+Assumptions!$D$33*Assumptions!$D$13)*Assumptions!$C$4*12 -> 26100 | H21: =(Assumptions!$D$12+Assumptions!$D$33*Assumptions!$D$13)*Assumptions!$C$4*12 -> 26100 | I21: =(Assumptions!$E$12+Assumptions!$E$33*Assumptions!$E$13)*Assumptions!$C$4*12 -> 15660 | J21: =(Assumptions!$E$12+Assumptions!$E$33*Assumptions!$E$13)*Assumptions!$C$4*12 -> 15660 | K21: =(Assumptions!$E$12+Assumptions!$E$33*Assumptions!$E$13)*Assumptions!$C$4*12 -> 15660
A22: Opex: replacement acquisition (customers × churn × cost to acquire) | B22: ₹ / yr | C22: =C$5*Assumptions!$C$27*'Unit economics'!$C$17 -> 475000 | D22: =D$5*Assumptions!$C$27*'Unit economics'!$C$17 -> 4750000 | E22: =E$5*Assumptions!$C$27*'Unit economics'!$C$17 -> 47500000 | F22: =F$5*Assumptions!$D$27*'Unit economics'!$D$17 -> 95400 | G22: =G$5*Assumptions!$D$27*'Unit economics'!$D$17 -> 954000 | H22: =H$5*Assumptions!$D$27*'Unit economics'!$D$17 -> 9540000 | I22: =I$5*Assumptions!$E$27*'Unit economics'!$E$17 -> 22600 | J22: =J$5*Assumptions!$E$27*'Unit economics'!$E$17 -> 226000 | K22: =K$5*Assumptions!$E$27*'Unit economics'!$E$17 -> 2260000
A23: Total opex | B23: ₹ / yr | C23: =SUM(C16:C22) -> 1902760 | D23: =SUM(D16:D22) -> 10977760 | E23: =SUM(E16:E22) -> 58527760 | F23: =SUM(F16:F22) -> 1357500 | G23: =SUM(G16:G22) -> 4016100 | H23: =SUM(H16:H22) -> 14402100 | I23: =SUM(I16:I22) -> 1174260 | J23: =SUM(J16:J22) -> 2877660 | K23: =SUM(K16:K22) -> 6411660
A24: EBITDA | B24: ₹ / yr | C24: =C13-C23 -> -541760 | D24: =D13-D23 -> 2632240 | E24: =E13-E23 -> 77572240 | F24: =F13-F23 -> 5148000 | G24: =G13-G23 -> 61038900 | H24: =H13-H23 -> 636147900 | I24: =I13-I23 -> 27131740 | J24: =J13-J23 -> 280182340 | K24: =K13-K23 -> 2824188340
A25: EBITDA margin | B25: % | C25: =IF(C11=0,0,C24/C11) -> -0.33339077 | D25: =IF(D11=0,0,D24/D11) -> 0.161984 | E25: =IF(E11=0,0,E24/E11) -> 0.47736763 | F25: =IF(F11=0,0,F24/F11) -> 0.77559322 | G25: =IF(G11=0,0,G24/G11) -> 0.91960678 | H25: =IF(H11=0,0,H24/H11) -> 0.95841492 | I25: =IF(I11=0,0,I24/I11) -> 0.95618467 | J25: =IF(J11=0,0,J24/J11) -> 0.98742675 | K25: =IF(K11=0,0,K24/K11) -> 0.99530867
A26: Reachable segment (organisations) | B26: count | C26: =Assumptions!$C$15 -> 900 | D26: =Assumptions!$C$15 -> 900 | E26: =Assumptions!$C$15 -> 900 | F26: =Assumptions!$D$15 -> 1500 | G26: =Assumptions!$D$15 -> 1500 | H26: =Assumptions!$D$15 -> 1500 | I26: =Assumptions!$E$15 -> 3000 | J26: =Assumptions!$E$15 -> 3000 | K26: =Assumptions!$E$15 -> 3000
A27: Customers reachable at the assumed win rate (segment × win rate) | B27: count | C27: =Assumptions!$C$15*Assumptions!$C$25 -> 45 | D27: =Assumptions!$C$15*Assumptions!$C$25 -> 45 | E27: =Assumptions!$C$15*Assumptions!$C$25 -> 45 | F27: =Assumptions!$D$15*Assumptions!$D$25 -> 150 | G27: =Assumptions!$D$15*Assumptions!$D$25 -> 150 | H27: =Assumptions!$D$15*Assumptions!$D$25 -> 150 | I27: =Assumptions!$E$15*Assumptions!$E$25 -> 600 | J27: =Assumptions!$E$15*Assumptions!$E$25 -> 600 | K27: =Assumptions!$E$15*Assumptions!$E$25 -> 600
A28: Feasibility flag | C28: =IF(C$5>Assumptions!$C$15,"EXCEEDS reachable segment",IF(C$5>Assumptions!$C$15*Assumptions!$C$25,"Needs "&TEXT(C$5/Assumptions!$C$15,"0%")&" of segment (> win rate)","Within reach")) -> Within reach | D28: =IF(D$5>Assumptions!$C$15,"EXCEEDS reachable segment",IF(D$5>Assumptions!$C$15*Assumptions!$C$25,"Needs "&TEXT(D$5/Assumptions!$C$15,"0%")&" of segment (> win rate)","Within reach")) -> Needs 11% of segment (> win rate) | E28: =IF(E$5>Assumptions!$C$15,"EXCEEDS reachable segment",IF(E$5>Assumptions!$C$15*Assumptions!$C$25,"Needs "&TEXT(E$5/Assumptions!$C$15,"0%")&" of segment (> win rate)","Within reach")) -> EXCEEDS reachable segment | F28: =IF(F$5>Assumptions!$D$15,"EXCEEDS reachable segment",IF(F$5>Assumptions!$D$15*Assumptions!$D$25,"Needs "&TEXT(F$5/Assumptions!$D$15,"0%")&" of segment (> win rate)","Within reach")) -> Within reach | G28: =IF(G$5>Assumptions!$D$15,"EXCEEDS reachable segment",IF(G$5>Assumptions!$D$15*Assumptions!$D$25,"Needs "&TEXT(G$5/Assumptions!$D$15,"0%")&" of segment (> win rate)","Within reach")) -> Within reach | H28: =IF(H$5>Assumptions!$D$15,"EXCEEDS reachable segment",IF(H$5>Assumptions!$D$15*Assumptions!$D$25,"Needs "&TEXT(H$5/Assumptions!$D$15,"0%")&" of segment (> win rate)","Within reach")) -> Needs 67% of segment (> win rate) | I28: =IF(I$5>Assumptions!$E$15,"EXCEEDS reachable segment",IF(I$5>Assumptions!$E$15*Assumptions!$E$25,"Needs "&TEXT(I$5/Assumptions!$E$15,"0%")&" of segment (> win rate)","Within reach")) -> Within reach | J28: =IF(J$5>Assumptions!$E$15,"EXCEEDS reachable segment",IF(J$5>Assumptions!$E$15*Assumptions!$E$25,"Needs "&TEXT(J$5/Assumptions!$E$15,"0%")&" of segment (> win rate)","Within reach")) -> Within reach | K28: =IF(K$5>Assumptions!$E$15,"EXCEEDS reachable segment",IF(K$5>Assumptions!$E$15*Assumptions!$E$25,"Needs "&TEXT(K$5/Assumptions!$E$15,"0%")&" of segment (> win rate)","Within reach")) -> Needs 33% of segment (> win rate)
A30: F1 — ISTS connectivity / GNA intelligence
A31: Customers | B31: count | C31: =C$5 -> 10 | D31: =D$5 -> 100 | E31: =E$5 -> 1000 | F31: =F$5 -> 10 | G31: =G$5 -> 100 | H31: =H$5 -> 1000 | I31: =I$5 -> 10 | J31: =J$5 -> 100 | K31: =K$5 -> 1000
A32: Recurring revenue (customers × steady-state ARPA) | B32: ₹ / yr | C32: =C$5*'Unit economics'!$C$29 -> 3000000 | D32: =D$5*'Unit economics'!$C$29 -> 30000000 | E32: =E$5*'Unit economics'!$C$29 -> 300000000 | F32: =F$5*'Unit economics'!$D$29 -> 6000000 | G32: =G$5*'Unit economics'!$D$29 -> 60000000 | H32: =H$5*'Unit economics'!$D$29 -> 600000000 | I32: =I$5*'Unit economics'!$E$29 -> 14000000 | J32: =J$5*'Unit economics'!$E$29 -> 140000000 | K32: =K$5*'Unit economics'!$E$29 -> 1400000000
A33: One-time fees on replacement customers (customers × churn × one-time fee) | B33: ₹ / yr | C33: =C$5*Assumptions!$C$50*'Unit economics'!$C$28 -> 0 | D33: =D$5*Assumptions!$C$50*'Unit economics'!$C$28 -> 0 | E33: =E$5*Assumptions!$C$50*'Unit economics'!$C$28 -> 0 | F33: =F$5*Assumptions!$D$50*'Unit economics'!$D$28 -> 0 | G33: =G$5*Assumptions!$D$50*'Unit economics'!$D$28 -> 0 | H33: =H$5*Assumptions!$D$50*'Unit economics'!$D$28 -> 0 | I33: =I$5*Assumptions!$E$50*'Unit economics'!$E$28 -> 0 | J33: =J$5*Assumptions!$E$50*'Unit economics'!$E$28 -> 0 | K33: =K$5*Assumptions!$E$50*'Unit economics'!$E$28 -> 0
A34: Total revenue | B34: ₹ / yr | C34: =C32+C33 -> 3000000 | D34: =D32+D33 -> 30000000 | E34: =E32+E33 -> 300000000 | F34: =F32+F33 -> 6000000 | G34: =G32+G33 -> 60000000 | H34: =H32+H33 -> 600000000 | I34: =I32+I33 -> 14000000 | J34: =J32+J33 -> 140000000 | K34: =K32+K33 -> 1400000000
A35: COGS (customers × variable cost) | B35: ₹ / yr | C35: =C$5*'Unit economics'!$C$32 -> 192000 | D35: =D$5*'Unit economics'!$C$32 -> 1920000 | E35: =E$5*'Unit economics'!$C$32 -> 19200000 | F35: =F$5*'Unit economics'!$D$32 -> 102000 | G35: =G$5*'Unit economics'!$D$32 -> 1020000 | H35: =H$5*'Unit economics'!$D$32 -> 10200000 | I35: =I$5*'Unit economics'!$E$32 -> 45000 | J35: =J$5*'Unit economics'!$E$32 -> 450000 | K35: =K$5*'Unit economics'!$E$32 -> 4500000
A36: Gross margin | B36: ₹ / yr | C36: =C34-C35 -> 2808000 | D36: =D34-D35 -> 28080000 | E36: =E34-E35 -> 280800000 | F36: =F34-F35 -> 5898000 | G36: =G34-G35 -> 58980000 | H36: =H34-H35 -> 589800000 | I36: =I34-I35 -> 13955000 | J36: =J34-J35 -> 139550000 | K36: =K34-K35 -> 1395500000
A37: Gross margin % | B37: % | C37: =IF(C34=0,0,C36/C34) -> 0.936 | D37: =IF(D34=0,0,D36/D34) -> 0.936 | E37: =IF(E34=0,0,E36/E34) -> 0.936 | F37: =IF(F34=0,0,F36/F34) -> 0.983 | G37: =IF(G34=0,0,G36/G34) -> 0.983 | H37: =IF(H34=0,0,H36/H34) -> 0.983 | I37: =IF(I34=0,0,I36/I34) -> 0.99678571 | J37: =IF(J34=0,0,J36/J34) -> 0.99678571 | K37: =IF(K34=0,0,K36/K34) -> 0.99678571
A38: Engineers at this stage (excl. founder) | B38: FTE | C38: =IF(C$5<=10,Assumptions!$C$58,IF(C$5<=100,Assumptions!$C$59,Assumptions!$C$60)) -> 0 | D38: =IF(D$5<=10,Assumptions!$C$58,IF(D$5<=100,Assumptions!$C$59,Assumptions!$C$60)) -> 2 | E38: =IF(E$5<=10,Assumptions!$C$58,IF(E$5<=100,Assumptions!$C$59,Assumptions!$C$60)) -> 3 | F38: =IF(F$5<=10,Assumptions!$D$58,IF(F$5<=100,Assumptions!$D$59,Assumptions!$D$60)) -> 0 | G38: =IF(G$5<=10,Assumptions!$D$58,IF(G$5<=100,Assumptions!$D$59,Assumptions!$D$60)) -> 1 | H38: =IF(H$5<=10,Assumptions!$D$58,IF(H$5<=100,Assumptions!$D$59,Assumptions!$D$60)) -> 2 | I38: =IF(I$5<=10,Assumptions!$E$58,IF(I$5<=100,Assumptions!$E$59,Assumptions!$E$60)) -> 0 | J38: =IF(J$5<=10,Assumptions!$E$58,IF(J$5<=100,Assumptions!$E$59,Assumptions!$E$60)) -> 1 | K38: =IF(K$5<=10,Assumptions!$E$58,IF(K$5<=100,Assumptions!$E$59,Assumptions!$E$60)) -> 2 | L38: Stage lookup on Assumptions eng10 / eng100 / eng1000.
A39: Opex: founder stipend | B39: ₹ / yr | C39: ='Path to first revenue'!$B$6*12 -> 600000 | D39: ='Path to first revenue'!$B$6*12 -> 600000 | E39: ='Path to first revenue'!$B$6*12 -> 600000 | F39: ='Path to first revenue'!$B$6*12 -> 600000 | G39: ='Path to first revenue'!$B$6*12 -> 600000 | H39: ='Path to first revenue'!$B$6*12 -> 600000 | I39: ='Path to first revenue'!$B$6*12 -> 600000 | J39: ='Path to first revenue'!$B$6*12 -> 600000 | K39: ='Path to first revenue'!$B$6*12 -> 600000 | L39: From Path to first revenue (input).
A40: Opex: engineers | B40: ₹ / yr | C40: =C38*Assumptions!$C$10*12 -> 0 | D40: =D38*Assumptions!$C$10*12 -> 4800000 | E40: =E38*Assumptions!$C$10*12 -> 7200000 | F40: =F38*Assumptions!$D$10*12 -> 0 | G40: =G38*Assumptions!$D$10*12 -> 1800000 | H40: =H38*Assumptions!$D$10*12 -> 3600000 | I40: =I38*Assumptions!$E$10*12 -> 0 | J40: =J38*Assumptions!$E$10*12 -> 1500000 | K40: =K38*Assumptions!$E$10*12 -> 3000000
A41: Opex: G&A fixed | B41: ₹ / yr | C41: =Assumptions!$C$11 -> 400000 | D41: =Assumptions!$C$11 -> 400000 | E41: =Assumptions!$C$11 -> 400000 | F41: =Assumptions!$D$11 -> 300000 | G41: =Assumptions!$D$11 -> 300000 | H41: =Assumptions!$D$11 -> 300000 | I41: =Assumptions!$E$11 -> 250000 | J41: =Assumptions!$E$11 -> 250000 | K41: =Assumptions!$E$11 -> 250000
A42: Opex: conferences / events | B42: ₹ / yr | C42: =Assumptions!$C$63 -> 200000 | D42: =Assumptions!$C$63 -> 200000 | E42: =Assumptions!$C$63 -> 200000 | F42: =Assumptions!$D$63 -> 150000 | G42: =Assumptions!$D$63 -> 150000 | H42: =Assumptions!$D$63 -> 150000 | I42: =Assumptions!$E$63 -> 100000 | J42: =Assumptions!$E$63 -> 100000 | K42: =Assumptions!$E$63 -> 100000
A43: Opex: fixed data / licence | B43: ₹ / yr | C43: =Assumptions!$C$54 -> 500000 | D43: =Assumptions!$C$54 -> 500000 | E43: =Assumptions!$C$54 -> 500000 | F43: =Assumptions!$D$54 -> 0 | G43: =Assumptions!$D$54 -> 0 | H43: =Assumptions!$D$54 -> 0 | I43: =Assumptions!$E$54 -> 0 | J43: =Assumptions!$E$54 -> 0 | K43: =Assumptions!$E$54 -> 0 | L43: CTUIL licence placeholder (unknown).
...

Sheet Sensitivity
A1: Sensitivity — F2, Base scenario (Assumptions column D), computed with formulas (no Data Tables)
A2: Section 1: one-way tornado on five drivers. Section 2: two-way grid, SaaS price × win rate. Section 3: calculation grid behind both (each column recomputes the full F2 chain with one driver moved).
A4: Low / high shock applied to each driver (input) | B4: -0.3 | C4: 0.3 | D4: ← −30% / +30% of the base value
A6: Section 1 — one-way sensitivities (tornado tables)
A7: Output: Payback months | B7: Base value | C7: Driver low value | D7: Driver high value | E7: Output @ low | F7: Output @ high | G7: Swing (abs)
A8: Base case | B8: =$B$93 -> 1.3894047
A9: SaaS price (₹/site/yr) | B9: =$B$61 -> 300000 | C9: =C$61 -> 210000 | D9: =D$61 -> 390000 | E9: =C$93 -> 1.8421434 | F9: =D$93 -> 1.1153003 | G9: =ABS(F9-E9) -> 0.72684307
A10: Win rate | B10: =$B$74 -> 0.1 | C10: =E$74 -> 0.07 | D10: =F$74 -> 0.13 | E10: =E$93 -> 1.8013576 | F10: =F$93 -> 1.1675839 | G10: =ABS(F10-E10) -> 0.63377365
A11: Recoverable % of bill | B11: =$B$64 -> 0.015 | C11: =G$64 -> 0.0105 | D11: =H$64 -> 0.0195 | E11: =G$93 -> 1.4803608 | F11: =H$93 -> 1.3089786 | G11: =ABS(F11-E11) -> 0.17138213
A12: Annual churn | B12: =$B$78 -> 0.15 | C12: =I$78 -> 0.105 | D12: =J$78 -> 0.195 | E12: =I$93 -> 1.3894047 | F12: =J$93 -> 1.3894047 | G12: =ABS(F12-E12) -> 0
A13: CAC driver: outbound hours per prospect | B13: =$B$72 -> 6 | C13: =K$72 -> 4.2 | D13: =L$72 -> 7.8 | E13: =K$93 -> 1.2321136 | F13: =L$93 -> 1.5466958 | G13: =ABS(F13-E13) -> 0.3145822
A15: Output: LTV / cost to acquire | B15: Base value | C15: Driver low value | D15: Driver high value | E15: Output @ low | F15: Output @ high | G15: Swing (abs)
A16: Base case | B16: =$B$94 -> 68.191824
A17: SaaS price (₹/site/yr) | B17: =$B$61 -> 300000 | C17: =C$61 -> 210000 | D17: =D$61 -> 390000 | E17: =C$94 -> 54.040881 | F17: =D$94 -> 82.342767 | G17: =ABS(F17-E17) -> 28.301887
A18: Win rate | B18: =$B$74 -> 0.1 | C18: =E$74 -> 0.07 | D18: =F$74 -> 0.13 | E18: =E$94 -> 52.59702 | F18: =F$94 -> 81.147093 | G18: =ABS(F18-E18) -> 28.550073
A19: Recoverable % of bill | B19: =$B$64 -> 0.015 | C19: =G$64 -> 0.0105 | D19: =H$64 -> 0.0195 | E19: =G$94 -> 61.470126 | F19: =H$94 -> 74.913522 | G19: =ABS(F19-E19) -> 13.443396
A20: Annual churn | B20: =$B$78 -> 0.15 | C20: =I$78 -> 0.105 | D20: =J$78 -> 0.195 | E20: =I$94 -> 92.868374 | F20: =J$94 -> 54.904451 | G20: =ABS(F20-E20) -> 37.963923
A21: CAC driver: outbound hours per prospect | B21: =$B$72 -> 6 | C21: =K$72 -> 4.2 | D21: =L$72 -> 7.8 | E21: =K$94 -> 76.897163 | F21: =L$94 -> 61.257062 | G21: =ABS(F21-E21) -> 15.640101
A23: Output: EBITDA at 100 customers (₹/yr) | B23: Base value | C23: Driver low value | D23: Driver high value | E23: Output @ low | F23: Output @ high | G23: Swing (abs)
A24: Base case | B24: =$B$95 -> 61038900
A25: SaaS price (₹/site/yr) | B25: =$B$61 -> 300000 | C25: =C$61 -> 210000 | D25: =D$61 -> 390000 | E25: =C$95 -> 47538900 | F25: =D$95 -> 74538900 | G25: =ABS(F25-E25) -> 27000000
A26: Win rate | B26: =$B$74 -> 0.1 | C26: =E$74 -> 0.07 | D26: =F$74 -> 0.13 | E26: =E$95 -> 60756043 | F26: =F$95 -> 61191208 | G26: =ABS(F26-E26) -> 435164.84
A27: Recoverable % of bill | B27: =$B$64 -> 0.015 | C27: =G$64 -> 0.0105 | D27: =H$64 -> 0.0195 | E27: =G$95 -> 54626400 | F27: =H$95 -> 67451400 | G27: =ABS(F27-E27) -> 12825000
A28: Annual churn | B28: =$B$78 -> 0.15 | C28: =I$78 -> 0.105 | D28: =J$78 -> 0.195 | E28: =I$95 -> 58287600 | F28: =J$95 -> 63790200 | G28: =ABS(F28-E28) -> 5502600
A29: CAC driver: outbound hours per prospect | B29: =$B$72 -> 6 | C29: =K$72 -> 4.2 | D29: =L$72 -> 7.8 | E29: =K$95 -> 61146900 | F29: =L$95 -> 60930900 | G29: =ABS(F29-E29) -> 216000
A31: Section 2 — two-way: SaaS price (rows) × win rate (columns)
A32: Output: Payback months (multipliers on base, blue = editable) | B32: price ↓ / win → | C32: 0.5 | D32: 0.7 | E32: 0.85 | F32: 1 | G32: 1.15 | H32: 1.3 | I32: 1.5
B33: win rate → | C33: =$B$74*C32 -> 0.05 | D33: =$B$74*D32 -> 0.07 | E33: =$B$74*E32 -> 0.085 | F33: =$B$74*F32 -> 0.1 | G33: =$B$74*G32 -> 0.115 | H33: =$B$74*H32 -> 0.13 | I33: =$B$74*I32 -> 0.15
A34: 0.5 | B34: =$B$61*A34 -> 150000 | C34: =IF((($B34*$B$62+$B$63*$B$62*$B$64*$B$65*$B$67)-($B$68+$B$69*12+$B$70*12*$B$71))<=0,999,((($B$72*$B$71+$B$73)/C$33+$B$75/$B$76)+$B$77*$B$71)/((($B34*$B$62+$B$63*$B$62*$B$64*$B$65*$B$67)-($B$68+$B$69*12+$B$70*12*$B$71))/12)) -> 3.9814986 | D34: =IF((($B34*$B$62+$B$63*$B$62*$B$64*$B$65*$B$67)-($B$68+$B$69*12+$B$70*12*$B$71))<=0,999,((($B$72*$B$71+$B$73)/D$33+$B$75/$B$76)+$B$77*$B$71)/((($B34*$B$62+$B$63*$B$62*$B$64*$B$65*$B$67)-($B$68+$B$69*12+$B$70*12*$B$71))/12)) -> 3.0511431 | E34: =IF((($B34*$B$62+$B$63*$B$62*$B$64*$B$65*$B$67)-($B$68+$B$69*12+$B$70*12*$B$71))<=0,999,((($B$72*$B$71+$B$73)/E$33+$B$75/$B$76)+$B$77*$B$71)/((($B34*$B$62+$B$63*$B$62*$B$64*$B$65*$B$67)-($B$68+$B$69*12+$B$70*12*$B$71))/12)) -> 2.6406922 | F34: =IF((($B34*$B$62+$B$63*$B$62*$B$64*$B$65*$B$67)-($B$68+$B$69*12+$B$70*12*$B$71))<=0,999,((($B$72*$B$71+$B$73)/F$33+$B$75/$B$76)+$B$77*$B$71)/((($B34*$B$62+$B$63*$B$62*$B$64*$B$65*$B$67)-($B$68+$B$69*12+$B$70*12*$B$71))/12)) -> 2.3533765 | G34: =IF((($B34*$B$62+$B$63*$B$62*$B$64*$B$65*$B$67)-($B$68+$B$69*12+$B$70*12*$B$71))<=0,999,((($B$72*$B$71+$B$73)/G$33+$B$75/$B$76)+$B$77*$B$71)/((($B34*$B$62+$B$63*$B$62*$B$64*$B$65*$B$67)-($B$68+$B$69*12+$B$70*12*$B$71))/12)) -> 2.1410127 | H34: =IF((($B34*$B$62+$B$63*$B$62*$B$64*$B$65*$B$67)-($B$68+$B$69*12+$B$70*12*$B$71))<=0,999,((($B$72*$B$71+$B$73)/H$33+$B$75/$B$76)+$B$77*$B$71)/((($B34*$B$62+$B$63*$B$62*$B$64*$B$65*$B$67)-($B$68+$B$69*12+$B$70*12*$B$71))/12)) -> 1.977656 | I34: =IF((($B34*$B$62+$B$63*$B$62*$B$64*$B$65*$B$67)-($B$68+$B$69*12+$B$70*12*$B$71))<=0,999,((($B$72*$B$71+$B$73)/I$33+$B$75/$B$76)+$B$77*$B$71)/((($B34*$B$62+$B$63*$B$62*$B$64*$B$65*$B$67)-($B$68+$B$69*12+$B$70*12*$B$71))/12)) -> 1.8106691
A35: 0.7 | B35: =$B$61*A35 -> 210000 | C35: =IF((($B35*$B$62+$B$63*$B$62*$B$64*$B$65*$B$67)-($B$68+$B$69*12+$B$70*12*$B$71))<=0,999,((($B$72*$B$71+$B$73)/C$33+$B$75/$B$76)+$B$77*$B$71)/((($B35*$B$62+$B$63*$B$62*$B$64*$B$65*$B$67)-($B$68+$B$69*12+$B$70*12*$B$71))/12)) -> 3.1165822 | D35: =IF((($B35*$B$62+$B$63*$B$62*$B$64*$B$65*$B$67)-($B$68+$B$69*12+$B$70*12*$B$71))<=0,999,((($B$72*$B$71+$B$73)/D$33+$B$75/$B$76)+$B$77*$B$71)/((($B35*$B$62+$B$63*$B$62*$B$64*$B$65*$B$67)-($B$68+$B$69*12+$B$70*12*$B$71))/12)) -> 2.3883314 | E35: =IF((($B35*$B$62+$B$63*$B$62*$B$64*$B$65*$B$67)-($B$68+$B$69*12+$B$70*12*$B$71))<=0,999,((($B$72*$B$71+$B$73)/E$33+$B$75/$B$76)+$B$77*$B$71)/((($B35*$B$62+$B$63*$B$62*$B$64*$B$65*$B$67)-($B$68+$B$69*12+$B$70*12*$B$71))/12)) -> 2.0670443 | F35: =IF((($B35*$B$62+$B$63*$B$62*$B$64*$B$65*$B$67)-($B$68+$B$69*12+$B$70*12*$B$71))<=0,999,((($B$72*$B$71+$B$73)/F$33+$B$75/$B$76)+$B$77*$B$71)/((($B35*$B$62+$B$63*$B$62*$B$64*$B$65*$B$67)-($B$68+$B$69*12+$B$70*12*$B$71))/12)) -> 1.8421434 | G35: =IF((($B35*$B$62+$B$63*$B$62*$B$64*$B$65*$B$67)-($B$68+$B$69*12+$B$70*12*$B$71))<=0,999,((($B$72*$B$71+$B$73)/G$33+$B$75/$B$76)+$B$77*$B$71)/((($B35*$B$62+$B$63*$B$62*$B$64*$B$65*$B$67)-($B$68+$B$69*12+$B$70*12*$B$71))/12)) -> 1.6759122 | H35: =IF((($B35*$B$62+$B$63*$B$62*$B$64*$B$65*$B$67)-($B$68+$B$69*12+$B$70*12*$B$71))<=0,999,((($B$72*$B$71+$B$73)/H$33+$B$75/$B$76)+$B$77*$B$71)/((($B35*$B$62+$B$63*$B$62*$B$64*$B$65*$B$67)-($B$68+$B$69*12+$B$70*12*$B$71))/12)) -> 1.5480421 | I35: =IF((($B35*$B$62+$B$63*$B$62*$B$64*$B$65*$B$67)-($B$68+$B$69*12+$B$70*12*$B$71))<=0,999,((($B$72*$B$71+$B$73)/I$33+$B$75/$B$76)+$B$77*$B$71)/((($B35*$B$62+$B$63*$B$62*$B$64*$B$65*$B$67)-($B$68+$B$69*12+$B$70*12*$B$71))/12)) -> 1.4173304
